<?xml version="1.0"?>

<robot name="pioneer3dx" xmlns:sensor="http://playerstage.sourceforge.net/gazebo/xmlschema/#sensor"
	   xmlns:controller="http://playerstage.sourceforge.net/gazebo/
	   xmlschema/#controller"
	   xmlns:interface="http://playerstage.sourceforge.net/gazebo/xmlschema/#interface"
	   xmlns:xacro="http://ros.org/wiki/xacro"
	   >


  <!-- import the pioneer 3dx's wheels -->
  <xacro:include filename="$(find ensta_robots)/urdf/pioneer3dx_wheel.xacro" />

	<include filename="$(find p2os_urdf)/defs/pioneer3dx_wheel.xacro"/>

	<link name="footprint">
		<visual>
			<geometry name="pioneer_geom">
				<box size="0.001 0.001 0.001"/>
			</geometry>
			<origin rpy="0 0 0" xyz="0 0 0"/>
			
		</visual>
	</link>


	<joint name="base_joint" type="fixed">
	  <parent link="footprint"/>
	  <child link="base_link"/>
	</joint>

	<gazebo reference="base_footprint">
 		<material value="Gazebo/Green"/>
 		
	</gazebo>

<!-- Chassis -->
	<link name="base_link">
		<!-- CHECK THESE VALUES. THEY MAY BE COMPLETELY WRONG. -->
		<inertial>
			<mass value="40.0"/>
			<origin xyz="-0.045 0 0.148"/>
			<inertia ixx="0.3338" ixy="0.0" ixz="0.0"
				 iyy="0.4783" iyz="0.0"
				 izz="0.3338"/>
		</inertial>
		<!-- The base visual is fine. Just the inertial is questionable.-->
		<visual name="pioneer_geom">
			<origin xyz="-0.045 0 0.148" rpy="0 0 0"/>
			<geometry name="pioneer_geom">
				<mesh filename="package://p2os_urdf/meshes/p3dx_meshes/chassis.stl"/>
			</geometry>
			<material name="ChassisRed">
				<color rgba="0.851 0.0 0.0 1.0"/>
			</material>
		</visual>
		<collision>
			<origin xyz="-0.045 0 0.148" rpy="0 0 0"/>
				<geometry>
					<mesh filename="package://p2os_urdf/meshes/p3dx_meshes/chassis.stl"/>
				</geometry>
		</collision>
	</link>
	<gazebo reference="base_link">
		<material value="Gazebo/Red"/>
	</gazebo>

	<link name="top_plate">
		<inertial>
			<mass value="0.01"/>	
			<origin xyz="0 0 0"/>
			<inertia ixx="1" ixy="0" ixz="0"
				 iyy="1" iyz="0"
 				izz="1"/>
		</inertial>
		<visual name="pioneer_geom">
			<origin xyz="0 0 0" rpy="0 0 0"/>
			<geometry name="pioneer_geom">
				<mesh filename="package://p2os_urdf/meshes/p3dx_meshes/top.stl"/>
			</geometry>
			<material name="TopBlack">
					<color rgba="0.038 0.038 0.038 1.0"/>
			</material>
		</visual>
	</link>
	<gazebo reference="top_plate">
		<material value="Gazebo/Black"/>
	</gazebo>

	<joint name="base_top_joint" type="fixed">
		<origin xyz="-0.045 0 0.24" rpy="0 0 0"/>
		<parent link="base_link"/>
		<child link="top_plate"/>
	</joint>

 <!-- swivel -->
	<link name="swivel">
		<inertial>
			<mass value="0.1" />
			<origin xyz="0 0 0" />
			<inertia ixx="0.01" ixy="0" ixz="0" iyy="0.01" iyz="0" izz="0.01" />
		</inertial>

		<visual name="base_visual">
			<origin xyz="0 0 0" rpy="0 0 0" />
			<geometry name="pioneer_geom">
				<mesh filename="package://p2os_urdf/meshes/p3dx_meshes/swivel.stl" />
			</geometry>
			<material name="swivel">
				<color rgba="0.5 0.5 0.5 1" />
			</material>
		</visual>

		<collision>
			<origin xyz="0 0 0" rpy="0 0 0" />
			<geometry>
				<box size="0 0 0" />
			</geometry>
		</collision>
	</link>

	<joint name="base_swivel_joint" type="continuous">
		<origin xyz="-0.185 0 0.050" rpy="0 0 0" />
		<axis xyz="0 0 1" />
		<anchor xyz="0 0 0" />
		<limit effort="100" velocity="100" k_velocity="0" />
		<joint_properties damping="0.0" friction="0.0" />
		<parent link="base_link" />
		<child link="swivel" />
	</joint>

	<!-- swivel -->
	  <gazebo reference="swivel">
	    <material>Gazebo/Grey</material>
	  </gazebo>

  <!-- center_hubcap -->
	<link name="center_hubcap">
		<inertial>
			<mass value="0.01" />
			<origin xyz="0 0 0" />
			<inertia ixx="0.012411765597" ixy="-0.000711733678" ixz="0.00050272983"
				iyy="0.015218160428" iyz="-0.000004273467" izz="0.011763977943" />
		</inertial>

		<visual name="base_visual">
			<origin xyz="0 0 0" rpy="0 0 0" />
			<geometry name="pioneer_geom">
				<mesh filename="package://p2os_urdf/meshes/p3dx_meshes/center_hubcap.stl" />
			</geometry>
			<material name="swivel">
				<color rgba="0.5 0.5 0.5 1" />
			</material>
		</visual>

		<collision>
			<origin xyz="0 0 0" rpy="0 0 0" />
			<geometry>
				<box size="0 0 0" />
			</geometry>
		</collision>
	</link>

	<joint name="swivel_hubcap_joint" type="continuous">
		<origin xyz="-0.026 0 -0.016" rpy="0 0 0" />
		<axis xyz="0 1 0" />
		<anchor xyz="0 0 0" />
		<limit effort="100" velocity="100" k_velocity="0" />
		<joint_properties damping="0.0" friction="0.0" />
		<parent link="swivel" />
		<child link="center_wheel" />
	</joint>

	<gazebo reference="center_hubcap">
		<material>Gazebo/Grey</material>
	</gazebo>
  <!-- center_wheel -->
	<link name="center_wheel">
		<inertial>
			<mass value="0.1" />
			<origin xyz="0 0 0" />
			<inertia ixx="0.012411765597" ixy="-0.000711733678" ixz="0.00050272983"
				iyy="0.015218160428" iyz="-0.000004273467" izz="0.011763977943" />
		</inertial>

		<visual name="base_visual">
			<origin xyz="0 0 0" rpy="0 0 0" />
			<geometry name="pioneer_geom">
				<mesh filename="package://p2os_urdf/meshes/p3dx_meshes/center_wheel.stl" />
			</geometry>
			<material name="WheelBlack">
				<color rgba="0.117 0.117 0.117 1" />
			</material>
		</visual>

		<collision>
			<origin xyz="0 0 0" rpy="${-3.1415927/2.0} 0 0" />
			<geometry>
				<cylinder radius="0.0375" length="0.01" />
			</geometry>
		</collision>
	</link>

	<joint name="center_wheel_joint" type="fixed">
		<origin xyz="-0.0035 0 -0.001" rpy="0 0 0"/>
		<parent link="center_wheel"/>
		<child link="center_hubcap"/>
	</joint>

	  <!-- center_wheel -->
	<gazebo reference="center_wheel">
		<material>Gazebo/Black</material>
		<mu1>1.0</mu1>
		<mu2>1.0</mu2>
		
	</gazebo>

	
<!-- Right wheel + hubcap -->
	<!-- wheel -->
	<link name="right_wheel">
	  <collision>
	    <origin xyz="0 0 0" rpy="${-3.1415927/2.0} 0 0"/>
	    <geometry>
		<cylinder radius="0.09" length="0.01"/>
	    </geometry>
	  </collision>
          <visual>
	    <origin xyz="0 0 0" rpy="0 0 0"/>
	 	<geometry>
	          <mesh filename="package://p2os_urdf/meshes/p3dx_meshes/right_wheel.stl"/>
		</geometry>
		<material name="WheelBlack">
		  <color rgba="0.117 0.117 0.117 1"/>
		</material>
	  </visual>
	  <inertial>
		<mass value="0.5" />
		<origin xyz="0 0 0" />
		<inertia ixx="0.012411765597" ixy="0" ixz="0" iyy="0.015218160428"
					iyz="0" izz="0.011763977943" />
	  </inertial>
	</link>
	

	<joint name="right_hub_joint" type="fixed">
		<origin xyz="0 0 0" rpy="0 0 0"/>
		<parent link="right_wheel"/>
		<child link="right_hub"/>
		
	</joint>		

	
	<!-- hubcap -->
	<link name="right_hub">
		<visual>
			<origin xyz="0 0 0" rpy="0 0 0"/>
			<geometry>
				<mesh filename="package://p2os_urdf/meshes/p3dx_meshes/right_hubcap.stl"/>
			</geometry>
			<material name="HubcapYellow">
				<color rgba="1.0 0.811 0.151 1.0"/>
			</material>
		</visual>
		<collision>
			<origin xyz="0 0 0" rpy="0 0 0"/>
			<geometry>
				
				<cylinder radius="0.09" length="0.01"/>
			</geometry>
		</collision>
	</link>

	<joint name="right_wheel_joint" type="continuous">
			<axis xyz="0 1 0" />
			<anchor xyz="0 0 0" />
			<limit effort="100" velocity="100" />
			<joint_properties damping="0.0" friction="0.0" />
			<origin xyz="0 -0.15 0.08" rpy="0 0 0" />
			<parent link="base_link" />
			<child link="right_wheel" />
			
			
	</joint>



	<gazebo reference="right_hub">
	   <material>Gazebo/Yellow</material>
	</gazebo>


	<gazebo reference="right_wheel">
		
		  <material>Gazebo/Black</material>
	</gazebo>
        
        <transmission name="right_trans">
	  <type>transmission_interface/SimpleTransmission</type>
	  <joint name="right_wheel_joint"/>
	  <actuator name="rightMotor">
	    <hardwareInterface>EffortJointInterface</hardwareInterface>
	    <mechanicalReduction>-1 * 624/35 * 80/19</mechanicalReduction>
	  </actuator>
	</transmission>
	

<!-- Left wheel + hubcap -->
	<!-- wheel -->
	<link name="left_wheel">
	  <collision>
	    <origin xyz="0 0 0" rpy="${-3.1415927/2.0} 0 0"/>
	    <geometry>
		<cylinder radius="0.09" length="0.01"/>
	    </geometry>
	  </collision>
          <visual>
	    <origin xyz="0 0 0" rpy="0 0 0"/>
	 	<geometry>
	          <mesh filename="package://p2os_urdf/meshes/p3dx_meshes/left_wheel.stl"/>
		</geometry>
		<material name="WheelBlack">
		  <color rgba="0.117 0.117 0.117 1"/>
		</material>
	  </visual>
	  <inertial>
		<mass value="0.5" />
		<origin xyz="0 0 0" />
		<inertia ixx="0.012411765597" ixy="0" ixz="0" iyy="0.015218160428"
					iyz="0" izz="0.011763977943" />
	  </inertial>
	</link>
	

	<joint name="left_hub_joint" type="fixed">
		<origin xyz="0 0 0" rpy="0 0 0"/>
		<parent link="left_wheel"/>
		<child link="left_hub"/>
		
	</joint>		

	
	<!-- hubcap -->
	<link name="left_hub">
		<visual>
			<origin xyz="0 0 0" rpy="0 0 0"/>
			<geometry>
				<mesh filename="package://p2os_urdf/meshes/p3dx_meshes/left_hubcap.stl"/>
			</geometry>
			<material name="HubcapYellow">
				<color rgba="1.0 0.811 0.151 1.0"/>
			</material>
		</visual>
		<collision>
			<origin xyz="0 0 0" rpy="0 0 0"/>
			<geometry>
				
				<cylinder radius="0.09" length="0.01"/>
			</geometry>
		</collision>
	</link>

	<joint name="left_wheel_joint" type="continuous">
			<axis xyz="0 1 0" />
			<anchor xyz="0 0 0" />
			<limit effort="100" velocity="100" />
			<joint_properties damping="0.0" friction="0.0" />
			<origin xyz="0 0.15 0.08" rpy="0 0 0" />
			<parent link="base_link" />
			<child link="left_wheel" />
			
			
	</joint>



	<gazebo reference="left_hub">
	   <material>Gazebo/Yellow</material>
	</gazebo>

		<gazebo reference="left_wheel">
		 
		  <material>Gazebo/Black</material>
		</gazebo>
	
        <transmission name="left_trans">
	  <type>transmission_interface/SimpleTransmission</type>
	  <joint name="left_wheel_joint"/>
	  <actuator name="leftMotor">
	    <hardwareInterface>EffortJointInterface</hardwareInterface>
	    <mechanicalReduction>-1 * 624/35 * 80/19</mechanicalReduction>
	  </actuator>
	</transmission>

<!-- Hokuyo Laser -->
	<link name="hokuyo_link">
		<inertial>
			<mass value="1e-5" />
			<origin xyz="0 0 0" rpy="0 0 0" />
			<inertia ixx="1e-6" ixy="0" ixz="0" iyy="1e-6" iyz="0" izz="1e-6" />
		</inertial>
		<visual>
			<origin xyz="0 0 0" rpy="0 0 0" />
			<geometry>
				<mesh filename="package://ensta_robots/meshes/hokuyo.dae" />     
			</geometry>
		</visual>

		<collision>
			<origin xyz="0 0 0" rpy="0 0 0" />
			<geometry>
				<box size="0.1 0.1 0.1" />
			</geometry>
		</collision>
	</link>
		

	<joint name="hokuyo_joint" type="fixed">
	    <axis xyz="0 1 0" />
	    <origin xyz="0.16 0 0.14" rpy="0 0 0"/>
	    <parent link="base_link"/>
	    <child link="hokuyo_link"/>
  	</joint>





<!--gazebo plugins -->

	<!-- ros_control plugin -->
	  <gazebo>
	    <plugin name="gazebo_ros_control" filename="libgazebo_ros_control.so">
	      <robotNamespace>/pioneer3dx</robotNamespace>
	    </plugin>
	  </gazebo>

	<!-- differential drive -->
	<gazebo>
		<plugin name="differential_drive_controller" filename="libgazebo_ros_diff_drive.so">
			<alwaysOn>true</alwaysOn>
			<updateRate>100</updateRate>
			<leftJoint>left_wheel_joint</leftJoint>
			<rightJoint>right_wheel_joint</rightJoint>
			<wheelSeparation>0.39</wheelSeparation>
			<wheelDiameter>0.15</wheelDiameter>
			<torque>5</torque>
			<commandTopic>pioneer3dx/cmd_vel</commandTopic>
			<odometryTopic>pioneer3dx/odom</odometryTopic>
			<odometryFrame>odom</odometryFrame>
			<robotBaseFrame>base_link</robotBaseFrame>
		</plugin>
			
		
	</gazebo>

<gazebo reference="hokuyo_link">
            		<sensor type="ray" name="head_hokuyo_sensor">
			<pose>0 0 0 0 0 0</pose>
			<visualize>1</visualize>
			<update_rate>50</update_rate>
			<ray>
				<scan>
					<horizontal>
						<samples>360</samples>
						<resolution>1</resolution>
						<min_angle>-1.570796</min_angle>
						<max_angle>1.570796</max_angle>
					</horizontal>
				</scan>
				<range>
					<min>0.10</min>
					<max>4.0</max>
					<resolution>0.01</resolution>
				</range>
				<noise>
					<type>gaussian</type>
					<!-- Noise parameters based on published spec for Hokuyo laser achieving 
						"+-30mm" accuracy at range < 10m. A mean of 0.0m and stddev of 0.01m will 
						put 99.7% of samples within 0.03m of the true reading. -->
					<mean>0.0</mean>
					<stddev>0.01</stddev>
				</noise>
			</ray>
			<plugin name="gazebo_ros_head_hokuyo_controller" filename="libgazebo_ros_laser.so">
				<topicName>/pioneer3dx/laserscan</topicName>
				<frameName>hokuyo_link</frameName>
			</plugin>
		</sensor>
        </gazebo>

	
  	  <!-- ground truth -->
	<gazebo>
		<plugin name="p3d_base_controller" filename="libgazebo_ros_p3d.so">
			<alwaysOn>true</alwaysOn>
			<updateRate>100.0</updateRate>
			<bodyName>base_link</bodyName>
			<topicName>pioneer3dx/base_pose_ground_truth</topicName>
			<gaussianNoise>0.01</gaussianNoise>
			<frameName>map</frameName>
			<!-- initialize odometry for fake localization -->
			<xyzOffsets>0 0 0</xyzOffsets>
			<rpyOffsets>0 0 0</rpyOffsets>
		</plugin>
	</gazebo>






	
</robot>
